[2025-01-02T06:42:53.891+0000] {local_task_job_runner.py:123} INFO - ::group::Pre task execution logs
[2025-01-02T06:42:53.924+0000] {taskinstance.py:2613} INFO - Dependencies all met for dep_context=non-requeueable deps ti=<TaskInstance: fetch_and_transform_news_data.process_news_all_countries manual__2025-01-02T06:42:50.114781+00:00 [queued]>
[2025-01-02T06:42:53.945+0000] {taskinstance.py:2613} INFO - Dependencies all met for dep_context=requeueable deps ti=<TaskInstance: fetch_and_transform_news_data.process_news_all_countries manual__2025-01-02T06:42:50.114781+00:00 [queued]>
[2025-01-02T06:42:53.947+0000] {taskinstance.py:2866} INFO - Starting attempt 1 of 2
[2025-01-02T06:42:53.995+0000] {taskinstance.py:2889} INFO - Executing <Task(PythonOperator): process_news_all_countries> on 2025-01-02 06:42:50.114781+00:00
[2025-01-02T06:42:54.018+0000] {warnings.py:112} WARNING - /home/***/.local/lib/python3.12/site-packages/***/task/task_runner/standard_task_runner.py:70: DeprecationWarning: This process (pid=261) is multi-threaded, use of fork() may lead to deadlocks in the child.
  pid = os.fork()

[2025-01-02T06:42:54.027+0000] {standard_task_runner.py:72} INFO - Started process 266 to run task
[2025-01-02T06:42:54.026+0000] {standard_task_runner.py:104} INFO - Running: ['***', 'tasks', 'run', 'fetch_and_transform_news_data', 'process_news_all_countries', 'manual__2025-01-02T06:42:50.114781+00:00', '--job-id', '90', '--raw', '--subdir', 'DAGS_FOLDER/fetch_and_transform_news.py', '--cfg-path', '/tmp/tmp8rk31a5j']
[2025-01-02T06:42:54.032+0000] {standard_task_runner.py:105} INFO - Job 90: Subtask process_news_all_countries
[2025-01-02T06:42:54.185+0000] {task_command.py:467} INFO - Running <TaskInstance: fetch_and_transform_news_data.process_news_all_countries manual__2025-01-02T06:42:50.114781+00:00 [running]> on host 4fe538676cbc
[2025-01-02T06:42:54.497+0000] {taskinstance.py:3132} INFO - Exporting env vars: AIRFLOW_CTX_DAG_OWNER='***' AIRFLOW_CTX_DAG_ID='fetch_and_transform_news_data' AIRFLOW_CTX_TASK_ID='process_news_all_countries' AIRFLOW_CTX_EXECUTION_DATE='2025-01-02T06:42:50.114781+00:00' AIRFLOW_CTX_TRY_NUMBER='1' AIRFLOW_CTX_DAG_RUN_ID='manual__2025-01-02T06:42:50.114781+00:00'
[2025-01-02T06:42:54.499+0000] {taskinstance.py:731} INFO - ::endgroup::
[2025-01-02T06:42:54.587+0000] {base.py:84} INFO - Retrieving connection 'snowflake_con'
[2025-01-02T06:42:54.589+0000] {connection.py:414} INFO - Snowflake Connector for Python Version: 3.12.4, Python Version: 3.12.8, Platform: Linux-5.15.167.4-microsoft-standard-WSL2-x86_64-with-glibc2.36
[2025-01-02T06:42:54.594+0000] {connection.py:1197} INFO - Connecting to GLOBAL Snowflake domain
[2025-01-02T06:42:54.595+0000] {connection.py:1278} INFO - This connection is in OCSP Fail Open Mode. TLS Certificates would be checked for validity and revocation status. Any other Certificate Revocation related exceptions or OCSP Responder failures would be disregarded in favor of connectivity.
[2025-01-02T06:42:56.707+0000] {cursor.py:1166} INFO - Number of results in first chunk: 1
[2025-01-02T06:42:56.710+0000] {logging_mixin.py:190} INFO - None
[2025-01-02T06:42:56.711+0000] {connection.py:789} INFO - closed
[2025-01-02T06:42:57.020+0000] {connection.py:795} INFO - No async queries seem to be running, deleting session
[2025-01-02T06:42:57.357+0000] {connection.py:414} INFO - Snowflake Connector for Python Version: 3.12.4, Python Version: 3.12.8, Platform: Linux-5.15.167.4-microsoft-standard-WSL2-x86_64-with-glibc2.36
[2025-01-02T06:42:57.363+0000] {connection.py:1197} INFO - Connecting to GLOBAL Snowflake domain
[2025-01-02T06:42:57.364+0000] {connection.py:1278} INFO - This connection is in OCSP Fail Open Mode. TLS Certificates would be checked for validity and revocation status. Any other Certificate Revocation related exceptions or OCSP Responder failures would be disregarded in favor of connectivity.
[2025-01-02T06:43:00.353+0000] {cursor.py:1166} INFO - Number of results in first chunk: 862
[2025-01-02T06:43:09.238+0000] {local_task_job_runner.py:346} WARNING - State of this instance has been externally set to failed. Terminating instance.
[2025-01-02T06:43:09.242+0000] {local_task_job_runner.py:245} INFO - ::endgroup::
[2025-01-02T06:43:09.245+0000] {process_utils.py:132} INFO - Sending 15 to group 266. PIDs of all processes in the group: [266]
[2025-01-02T06:43:09.246+0000] {process_utils.py:87} INFO - Sending the signal 15 to group 266
[2025-01-02T06:43:09.247+0000] {taskinstance.py:3093} ERROR - Received SIGTERM. Terminating subprocesses.
[2025-01-02T06:43:11.081+0000] {connection.py:789} INFO - closed
[2025-01-02T06:43:11.387+0000] {connection.py:795} INFO - No async queries seem to be running, deleting session
[2025-01-02T06:43:11.792+0000] {taskinstance.py:340} INFO - ::group::Post task execution logs
[2025-01-02T06:43:11.858+0000] {process_utils.py:80} INFO - Process psutil.Process(pid=266, status='terminated', exitcode=0, started='06:42:53') (266) terminated with exit code 0
